Workbook

Sheet README
A1: Section | B1: Content
A2: Purpose | B2: Full-season 2026 ESPN full-PPR point forecasts and a calibrated probability of a missed-time injury for every fantasy-position player on the August 9, 2026 roster snapshot, combined into a transparent draft score.
A3: Forecast origin | B3: Inputs are frozen as of 2026-08-09. No 2026 statistics, depth charts, injury reports, projections, or ADP enter either model. The current-injury listing columns come from a separate dated screen (2026-08-14) and do not change the models.
A4: Overall Draft Score | B4: Cross-position ranking used on the ALL page. Points Over Replacement = projected points minus the projected points of the replacement-level player at the position (QB12, RB24, WR36, TE12, K12). Overall Value = points over replacement divided by the largest points over replacement on the board (negative values count as 0), so magnitudes are preserved across positions. It is blended with the player's healthy probability relative to position peers: 100 * ((1 - w) * overall value + w * (healthy probability - position mean healthy probability + 0.5)), w = 0.20. Centering on the position mean stops low-exposure positions such as kickers from gaining a blanket bonus. The custom-weight column on ALL uses the overall value and relative health columns.
A5: Position Draft Score | B5: Within-position ranking used on the QB, RB, WR, TE, and K pages: 100 * ((1 - w) * position points percentile + w * healthy probability) with the default w = 0.20, the largest weight whose discovery-fold rank accuracy against realized points stayed within 0.005 Spearman of the best weight. Edit SETTINGS!B2 to recompute the custom-weight column on every page.
A6: Projected 2026 Points | B6: Points track forecast: ext_et_all (components: ext_et_all). Locked 2022-2025 audit mean within-position-season Spearman 0.756 (95% player-cluster interval 0.732 to 0.775); prior-season points baseline 0.647. Kicker forecasts retain the Phase 2 production model and are labeled low confidence.
A7: Points P10 / P90 | B7: Empirical 10th and 90th percentile bounds from 2022-2025 audit residuals of the adopted procedure within position and predicted-point tercile. About 80% of realized totals fell inside this band on the audit seasons; it is not a guarantee.
A8: Missed-Time Injury Probability | B8: Probability that the player appears on an official report as Out or Doubtful with a physical injury, or is placed on an injury reserve list, at least once during the 2026 regular season. Model: extra_trees_all_leaf50; 2022-2024 audit ROC AUC 0.749 (95% interval 0.731 to 0.767), calibration slope 1.02, prevalence 24.7%. The label is an observed absence event, not severity or games missed, and participation is part of the signal.
A9: Injury Risk Band | B9: lower < 20%, moderate 20% to 35%, higher > 35% predicted probability.
A10: Current Injury Listing | B10: TRUE when the 2026-08-14 public screen matched an affirmative injury listing. FALSE is not evidence of health. The INJURED page repeats these players with their source details.
A11: Sheets | B11: ALL and INJURED sort by the overall draft score; QB, RB, WR, TE, and K sort by the position draft score. MODEL_EVAL, WEIGHT_ANALYSIS, FEATURES_POINTS, FEATURES_INJURY, and FAMILY_ABLATION hold the evaluation evidence and feature rankings.
A12: Leakage controls | B12: Historical candidates are prior-season roster members plus draft or combine entrants; nonparticipants keep zero points. Features use only seasons before the target. Report-based injury history uses offsets of two or more seasons because the official feed ends in 2024; roster reserve history uses offsets of one or more seasons. Model selection used 2016-2021 (points) and 2017-2021 (injury); audits ran once on 2022-2025 and 2022-2024. Negative controls: points null mean Spearman 0.0210; injury null mean AUC 0.5288.
... A14: Generated | B14: 2026-08-22T20:09:20.902824+00:00

Sheet SETTINGS
A1: Setting | B1: Value | C1: Note
A2: Injury weight used by the custom score column (0 to 1) | B2: 0.2 | C2: Edit this cell. Position pages recompute their custom score as 100 * ((1 - weight) * position points percentile + weight * healthy probability); ALL and INJURED use the overall value percentile instead. Rows stay in default order; use the column filter to re-sort.
A3: Default injury weight selected by the predeclared rule | B3: 0.2 | C3: Largest weight whose discovery-fold rank accuracy against realized points stayed within 0.005 Spearman of the best weight.

Sheet ALL
A1: Rank | B1: Player | C1: Team | D1: Pos | E1: Overall Draft Score (replacement-adjusted) | F1: Position Draft Score (default weight) | G1: Custom-Weight Score (weight from SETTINGS) | H1: Projected 2026 Points | I1: Points Over Replacement | J1: Overall Value (points over replacement / max) | K1: Points P10 | L1: Points P90 | M1: Pos Points Rank | N1: Pos Points Percentile | O1: Missed-Time Injury Probability | P1: Healthy Probability | Q1: Healthy Probability vs Position Mean (+0.5) | R1: Injury Risk Band | S1: Current Injury Listing (screen date) | T1: Current Listing Status | U1: Rookie | V1: Age | W1: Points Model Confidence | X1: Roster Status (Aug 9) | Y1: Player ID
A2: 1 | B2: Jaxon Smith-Njigba | C2: SEA | D2: WR | E2: 85.74 | F2: 90.68 | G2: =ROUND(100*((1-SETTINGS!$B$2)*J2+SETTINGS!$B$2*Q2),2) | H2: 249.73827 | I2: 127.25 | J2: 1 | K2: 181.94645 | L2: 332.01905 | M2: 1 | N2: 1 | O2: 0.46595868 | P2: 0.53404132 | Q2: 0.28689485 | R2: higher | S2: FALSE | U2: no | V2: 24.545336 | W2: standard | X2: ACT | Y2: 00-0038543
A3: 2 | B3: Amon-Ra St. Brown | C3: DET | D3: WR | E3: 75.19 | F3: 91.13 | G3: =ROUND(100*((1-SETTINGS!$B$2)*J3+SETTINGS!$B$2*Q3),2) | H3: 231.91781 | I3: 109.43 | J3: 0.86 | K3: 164.12599 | L3: 314.19859 | M3: 2 | N3: 0.99739583 | O3: 0.43314403 | P3: 0.56685597 | Q3: 0.3197095 | R3: higher | S3: FALSE | U3: no | V3: 26.856131 | W3: standard | X3: ACT | Y3: 00-0036963
A4: 3 | B4: Puka Nacua | C4: LA | D4: WR | E4: 74.24 | F4: 90.38 | G4: =ROUND(100*((1-SETTINGS!$B$2)*J4+SETTINGS!$B$2*Q4),2) | H4: 231.26732 | I4: 108.78 | J4: 0.8549 | K4: 163.4755 | L4: 313.5481 | M4: 3 | N4: 0.99479167 | O4: 0.46033059 | P4: 0.53966941 | Q4: 0.29252294 | R4: higher | S4: TRUE | T4: Questionable | U4: no | V4: 25.25993 | W4: standard | X4: ACT | Y4: 00-0039075
A5: 4 | B5: Bijan Robinson | C5: ATL | D5: RB | E5: 72.02 | F5: 88.24 | G5: =ROUND(100*((1-SETTINGS!$B$2)*J5+SETTINGS!$B$2*Q5),2) | H5: 264.68583 | I5: 107.69 | J5: 0.8463 | K5: 195.52625 | L5: 379.65372 | M5: 1 | N5: 1 | O5: 0.58776347 | P5: 0.41223653 | Q5: 0.21567287 | R5: higher | S5: FALSE | U5: no | V5: 24.586405 | W5: standard | X5: ACT | Y5: 00-0038542
A6: 5 | B6: Trey McBride | C6: AZ | D6: TE | E6: 70.59 | F6: 90.75 | G6: =ROUND(100*((1-SETTINGS!$B$2)*J6+SETTINGS!$B$2*Q6),2) | H6: 226.95633 | I6: 102.03 | J6: 0.8018 | K6: 183.20548 | L6: 299.83355 | M6: 1 | N6: 1 | O6: 0.46235352 | P6: 0.53764648 | Q6: 0.32240833 | R6: higher | S6: FALSE | U6: no | V6: 26.77673 | W6: standard | X6: ACT | Y6: 00-0037744
A7: 6 | B7: Josh Allen | C7: BUF | D7: QB | E7: 70.39 | F7: 91.32 | G7: =ROUND(100*((1-SETTINGS!$B$2)*J7+SETTINGS!$B$2*Q7),2) | H7: 322.74206 | I7: 102.95 | J7: 0.809 | K7: 213.08296 | L7: 463.3179 | M7: 1 | N7: 1 | O7: 0.43420955 | P7: 0.56579045 | Q7: 0.28356424 | R7: higher | S7: FALSE | U7: no | V7: 30.281252 | W7: standard | X7: ACT | Y7: 00-0034857
A8: 7 | B8: Ja'Marr Chase | C8: CIN | D8: WR | E8: 65.83 | F8: 91.81 | G8: =ROUND(100*((1-SETTINGS!$B$2)*J8+SETTINGS!$B$2*Q8),2) | H8: 215.27921 | I8: 92.79 | J8: 0.7292 | K8: 147.48739 | L8: 297.55999 | M8: 4 | N8: 0.9921875 | O8: 0.37819061 | P8: 0.62180939 | Q8: 0.37466292 | R8: higher | S8: FALSE | U8: no | V8: 26.502939 | W8: standard | X8: ACT | Y8: 00-0036900
A9: 8 | B9: George Pickens | C9: DAL | D9: WR | E9: 63.88 | F9: 91.25 | G9: =ROUND(100*((1-SETTINGS!$B$2)*J9+SETTINGS!$B$2*Q9),2) | H9: 212.40207 | I9: 89.92 | J9: 0.7066 | K9: 144.61025 | L9: 294.68285 | M9: 6 | N9: 0.98697917 | O9: 0.38547724 | P9: 0.61452276 | Q9: 0.36737629 | R9: higher | S9: FALSE | U9: no | V9: 25.49539 | W9: standard | X9: ACT | Y9: 00-0037247
A10: 9 | B10: Justin Jefferson | C10: MIN | D10: WR | E10: 63.83 | F10: 91.03 | G10: =ROUND(100*((1-SETTINGS!$B$2)*J10+SETTINGS!$B$2*Q10),2) | H10: 213.00414 | I10: 90.52 | J10: 0.7114 | K10: 145.21232 | L10: 295.28492 | M10: 5 | N10: 0.98958333 | O10: 0.4070599 | P10: 0.5929401 | Q10: 0.34579363 | R10: higher | S10: FALSE | U10: no | V10: 27.212057 | W10: standard | X10: ACT | Y10: 00-0036322
A11: 10 | B11: Zay Flowers | C11: BAL | D11: WR | E11: 59.1 | F11: 89.65 | G11: =ROUND(100*((1-SETTINGS!$B$2)*J11+SETTINGS!$B$2*Q11),2) | H11: 206.67381 | I11: 84.19 | J11: 0.6616 | K11: 138.88199 | L11: 288.95459 | M11: 8 | N11: 0.98177083 | O11: 0.44443044 | P11: 0.55556956 | Q11: 0.30842309 | R11: higher | S11: FALSE | U11: no | V11: 25.971786 | W11: standard | X11: ACT | Y11: 00-0039064
A12: 11 | B12: CeeDee Lamb | C12: DAL | D12: WR | E12: 58.45 | F12: 89.03 | G12: =ROUND(100*((1-SETTINGS!$B$2)*J12+SETTINGS!$B$2*Q12),2) | H12: 206.9714 | I12: 84.49 | J12: 0.664 | K12: 139.17958 | L12: 289.25218 | M12: 7 | N12: 0.984375 | O12: 0.48621738 | P12: 0.51378262 | Q12: 0.26663615 | R12: higher | S12: FALSE | U12: no | V12: 27.400974 | W12: standard | X12: ACT | Y12: 00-0036358
A13: 12 | B13: Jahmyr Gibbs | C13: DET | D13: RB | E13: 56.76 | F13: 87.83 | G13: =ROUND(100*((1-SETTINGS!$B$2)*J13+SETTINGS!$B$2*Q13),2) | H13: 240.4644 | I13: 83.47 | J13: 0.656 | K13: 171.30482 | L13: 355.4323 | M13: 2 | N13: 0.9952381 | O13: 0.5893529 | P13: 0.4106471 | Q13: 0.21408344 | R13: higher | S13: TRUE | T13: Questionable | U13: no | V13: 24.452248 | W13: standard | X13: ACT | Y13: 00-0039139
A14: 13 | B14: Jameson Williams | C14: DET | D14: WR | E14: 54.7 | F14: 88.93 | G14: =ROUND(100*((1-SETTINGS!$B$2)*J14+SETTINGS!$B$2*Q14),2) | H14: 200.4812 | I14: 78 | J14: 0.613 | K14: 132.68938 | L14: 282.76198 | M14: 9 | N14: 0.97916667 | O14: 0.47008001 | P14: 0.52991999 | Q14: 0.28277352 | R14: higher | S14: FALSE | U14: no | V14: 25.435156 | W14: standard | X14: ACT | Y14: 00-0037240
A15: 14 | B15: Derrick Henry | C15: BAL | D15: RB | E15: 52.62 | F15: 89.34 | G15: =ROUND(100*((1-SETTINGS!$B$2)*J15+SETTINGS!$B$2*Q15),2) | H15: 230.26795 | I15: 73.27 | J15: 0.5758 | K15: 161.10837 | L15: 345.23584 | M15: 4 | N15: 0.98571429 | O15: 0.47582579 | P15: 0.52417421 | Q15: 0.32761055 | R15: higher | S15: FALSE | U15: no | V15: 32.657753 | W15: standard | X15: ACT | Y15: 00-0032764
A16: 15 | B16: Drake London | C16: ATL | D16: WR | E16: 52.09 | F16: 87.69 | G16: =ROUND(100*((1-SETTINGS!$B$2)*J16+SETTINGS!$B$2*Q16),2) | H16: 197.9819 | I16: 75.5 | J16: 0.5933 | K16: 130.19008 | L16: 280.26269 | M16: 10 | N16: 0.9765625 | O16: 0.52163641 | P16: 0.47836359 | Q16: 0.23121712 | R16: higher | S16: FALSE | U16: no | V16: 25.106607 | W16: standard | X16: ACT | Y16: 00-0037238
A17: 16 | B17: De'Von Achane | C17: MIA | D17: RB | E17: 51.29 | F17: 87.47 | G17: =ROUND(100*((1-SETTINGS!$B$2)*J17+SETTINGS!$B$2*Q17),2) | H17: 231.74679 | I17: 74.75 | J17: 0.5874 | K17: 162.58721 | L17: 346.71469 | M17: 3 | N17: 0.99047619 | O17: 0.58838759 | P17: 0.41161241 | Q17: 0.21504875 | R17: higher | S17: FALSE | U17: no | V17: 24.884836 | W17: standard | X17: ACT | Y17: 00-0039040
A18: 17 | B18: Ashton Jeanty | C18: LV | D18: RB | E18: 46.99 | F18: 87.67 | G18: =ROUND(100*((1-SETTINGS!$B$2)*J18+SETTINGS!$B$2*Q18),2) | H18: 223.37205 | I18: 66.38 | J18: 0.5217 | K18: 154.21247 | L18: 338.33995 | M18: 5 | N18: 0.98095238 | O18: 0.54054458 | P18: 0.45945542 | Q18: 0.26289176 | R18: higher | S18: FALSE | U18: no | V18: 22.749269 | W18: standard | X18: ACT | Y18: 00-0040122
A19: 18 | B19: Tetairoa McMillan | C19: CAR | D19: WR | E19: 43.19 | F19: 87.24 | G19: =ROUND(100*((1-SETTINGS!$B$2)*J19+SETTINGS!$B$2*Q19),2) | H19: 184.2247 | I19: 61.74 | J19: 0.4852 | K19: 116.43288 | L19: 266.50548 | M19: 11 | N19: 0.97395833 | O19: 0.53396651 | P19: 0.46603349 | Q19: 0.21888702 | R19: higher | S19: FALSE | U19: no | V19: 23.409105 | W19: standard | X19: ACT | Y19: 00-0040124
A20: 19 | B20: Chris Olave | C20: NO | D20: WR | E20: 42.78 | F20: 89.86 | G20: =ROUND(100*((1-SETTINGS!$B$2)*J20+SETTINGS!$B$2*Q20),2) | H20: 178.73788 | I20: 56.25 | J20: 0.442 | K20: 110.94606 | L20: 261.01867 | M20: 13 | N20: 0.96875 | O20: 0.38199551 | P20: 0.61800449 | Q20: 0.37085802 | R20: higher | S20: FALSE | U20: no | V20: 26.179867 | W20: standard | X20: ACT | Y20: 00-0037239
A21: 20 | B21: Chase Brown | C21: CIN | D21: RB | E21: 41.07 | F21: 87.19 | G21: =ROUND(100*((1-SETTINGS!$B$2)*J21+SETTINGS!$B$2*Q21),2) | H21: 214.10578 | I21: 57.11 | J21: 0.4488 | K21: 144.9462 | L21: 329.07368 | M21: 6 | N21: 0.97619048 | O21: 0.54521446 | P21: 0.45478554 | Q21: 0.25822187 | R21: higher | S21: FALSE | U21: no | V21: 26.448181 | W21: standard | X21: ACT | Y21: 00-0038597
A22: 21 | B22: Nico Collins | C22: HOU | D22: WR | E22: 40.99 | F22: 87.95 | G22: =ROUND(100*((1-SETTINGS!$B$2)*J22+SETTINGS!$B$2*Q22),2) | H22: 179.27048 | I22: 56.78 | J22: 0.4462 | K22: 111.47866 | L22: 261.55126 | M22: 12 | N22: 0.97135417 | O22: 0.48793958 | P22: 0.51206042 | Q22: 0.26491395 | R22: higher | S22: FALSE | U22: no | V22: 27.455732 | W22: standard | X22: ACT | Y22: 00-0036554
A23: 22 | B23: Jaylen Waddle | C23: DEN | D23: WR | E23: 40.4 | F23: 87.71 | G23: =ROUND(100*((1-SETTINGS!$B$2)*J23+SETTINGS!$B$2*Q23),2) | H23: 178.02173 | I23: 55.54 | J23: 0.4365 | K23: 110.22991 | L23: 260.30251 | M23: 14 | N23: 0.96614583 | O23: 0.47908948 | P23: 0.52091052 | Q23: 0.27376405 | R23: higher | S23: TRUE | T23: Questionable | U23: no | V23: 27.767853 | W23: standard | X23: ACT | Y23: 00-0036613
A24: 23 | B24: A.J. Brown | C24: NE | D24: WR | E24: 39.58 | F24: 87.66 | G24: =ROUND(100*((1-SETTINGS!$B$2)*J24+SETTINGS!$B$2*Q24),2) | H24: 176.48154 | I24: 54 | J24: 0.4244 | K24: 108.68972 | L24: 258.76232 | M24: 15 | N24: 0.96354167 | O24: 0.47129817 | P24: 0.52870183 | Q24: 0.28155536 | R24: higher | S24: FALSE | U24: no | V24: 29.1724 | W24: standard | X24: ACT | Y24: 00-0035676
A25: 24 | B25: DeVonta Smith | C25: PHI | D25: WR | E25: 38.66 | F25: 87.49 | G25: =ROUND(100*((1-SETTINGS!$B$2)*J25+SETTINGS!$B$2*Q25),2) | H25: 174.96752 | I25: 52.48 | J25: 0.4124 | K25: 107.1757 | L25: 257.2483 | M25: 16 | N25: 0.9609375 | O25: 0.46928457 | P25: 0.53071543 | Q25: 0.28356896 | R25: higher | S25: TRUE | T25: Questionable | U25: no | V25: 27.79797 | W25: standard | X25: ACT | Y25: 00-0036912
A26: 25 | B26: Drake Maye | C26: NE | D26: QB | E26: 38.27 | F26: 90.36 | G26: =ROUND(100*((1-SETTINGS!$B$2)*J26+SETTINGS!$B$2*Q26),2) | H26: 272.09196 | I26: 52.3 | J26: 0.411 | K26: 162.43286 | L26: 412.6678 | M26: 2 | N26: 0.99159664 | O26: 0.44824514 | P26: 0.55175486 | Q26: 0.26952865 | R26: higher | S26: FALSE | U26: no | V26: 24.005968 | W26: standard | X26: ACT | Y26: 00-0039851
A27: 26 | B27: Wan'Dale Robinson | C27: TEN | D27: WR | E27: 36.18 | F27: 86.88 | G27: =ROUND(100*((1-SETTINGS!$B$2)*J27+SETTINGS!$B$2*Q27),2) | H27: 171.65199 | I27: 49.17 | J27: 0.3864 | K27: 103.86017 | L27: 253.93278 | M27: 17 | N27: 0.95833333 | O27: 0.48954781 | P27: 0.51045219 | Q27: 0.26330572 | R27: higher | S27: FALSE | U27: no | V27: 25.654188 | W27: standard | X27: ACT | Y27: 00-0038117
A28: 27 | B28: Jalen Hurts | C28: PHI | D28: QB | E28: 34.96 | F28: 89.23 | G28: =ROUND(100*((1-SETTINGS!$B$2)*J28+SETTINGS!$B$2*Q28),2) | H28: 267.55492 | I28: 47.76 | J28: 0.3753 | K28: 157.89582 | L28: 408.13076 | M28: 3 | N28: 0.98319328 | O28: 0.47105394 | P28: 0.52894606 | Q28: 0.24671986 | R28: higher | S28: FALSE | U28: no | V28: 28.069023 | W28: standard | X28: ACT | Y28: 00-0036389
A29: 28 | B29: Emeka Egbuka | C29: TB | D29: WR | E29: 33.62 | F29: 85.8 | G29: =ROUND(100*((1-SETTINGS!$B$2)*J29+SETTINGS!$B$2*Q29),2) | H29: 168.97355 | I29: 46.49 | J29: 0.3653 | K29: 101.18173 | L29: 251.25433 | M29: 18 | N29: 0.95572917 | O29: 0.53296324 | P29: 0.46703676 | Q29: 0.21989029 | R29: higher | S29: TRUE | T29: Questionable | U29: no | V29: 23.882763 | W29: standard | X29: ACT | Y29: 00-0040129
A30: 29 | B30: Caleb Williams | C30: CHI | D30: QB | E30: 33.32 | F30: 89.49 | G30: =ROUND(100*((1-SETTINGS!$B$2)*J30+SETTINGS!$B$2*Q30),2) | H30: 263.46877 | I30: 43.68 | J30: 0.3433 | K30: 153.80967 | L30: 404.04461 | M30: 4 | N30: 0.97478992 | O30: 0.42488997 | P30: 0.57511003 | Q30: 0.29288382 | R30: higher | S30: FALSE | U30: no | V30: 24.786272 | W30: standard | X30: ACT | Y30: 00-0039918
A31: 30 | B31: Harold Fannin Jr. | C31: CLE | D31: TE | E31: 33.07 | F31: 89.22 | G31: =ROUND(100*((1-SETTINGS!$B$2)*J31+SETTINGS!$B$2*Q31),2) | H31: 168.4083 | I31: 43.48 | J31: 0.3417 | K31: 124.65745 | L31: 241.28552 | M31: 3 | N31: 0.98974359 | O31: 0.49803494 | P31: 0.50196506 | Q31: 0.28672691 | R31: higher | S31: FALSE | U31: no | V31: 22.116814 | W31: standard | X31: ACT | Y31: 00-0040663
A32: 31 | B32: Kyle Pitts | C32: ATL | D32: TE | E32: 33 | F32: 89.2 | G32: =ROUND(100*((1-SETTINGS!$B$2)*J32+SETTINGS!$B$2*Q32),2) | H32: 168.98125 | I32: 44.05 | J32: 0.3462 | K32: 125.23039 | L32: 241.85847 | M32: 2 | N32: 0.99487179 | O32: 0.51970839 | P32: 0.48029161 | Q32: 0.26505346 | R32: higher | S32: FALSE | U32: no | V32: 25.903337 | W32: standard | X32: ACT | Y32: 00-0036970
A33: 32 | B33: Travis Kelce | C33: KC | D33: TE | E33: 32.04 | F33: 91.02 | G33: =ROUND(100*((1-SETTINGS!$B$2)*J33+SETTINGS!$B$2*Q33),2) | H33: 162.60426 | I33: 37.68 | J33: 0.2961 | K33: 118.85341 | L33: 235.48148 | M33: 5 | N33: 0.97948718 | O33: 0.36695746 | P33: 0.63304254 | Q33: 0.41780439 | R33: higher | S33: FALSE | U33: no | V33: 36.906986 | W33: standard | X33: ACT | Y33: 00-0030506
A34: 33 | B34: Kyren Williams | C34: LA | D34: RB | E34: 31.7 | F34: 87.72 | G34: =ROUND(100*((1-SETTINGS!$B$2)*J34+SETTINGS!$B$2*Q34),2) | H34: 197.75366 | I34: 40.76 | J34: 0.3203 | K34: 128.59408 | L34: 312.72156 | M34: 7 | N34: 0.97142857 | O34: 0.49950467 | P34: 0.50049533 | Q34: 0.30393166 | R34: higher | S34: FALSE | U34: no | V34: 26.015593 | W34: standard | X34: ACT | Y34: 00-0037840
A35: 34 | B35: Michael Wilson | C35: AZ | D35: WR | E35: 31.45 | F35: 85.88 | G35: =ROUND(100*((1-SETTINGS!$B$2)*J35+SETTINGS!$B$2*Q35),2) | H35: 165.04877 | I35: 42.56 | J35: 0.3345 | K35: 97.25695 | L35: 247.32955 | M35: 19 | N35: 0.953125 | O35: 0.51845499 | P35: 0.48154501 | Q35: 0.23439854 | R35: higher | S35: FALSE | U35: no | V35: 26.522104 | W35: standard | X35: ACT | Y35: 00-0038559
A36: 35 | B36: Davante Adams | C36: LA | D36: WR | E36: 31.12 | F36: 86.65 | G36: =ROUND(100*((1-SETTINGS!$B$2)*J36+SETTINGS!$B$2*Q36),2) | H36: 162.3029 | I36: 39.82 | J36: 0.3129 | K36: 94.511082 | L36: 244.58368 | M36: 22 | N36: 0.9453125 | O36: 0.44855853 | P36: 0.55144147 | Q36: 0.30429499 | R36: higher | S36: FALSE | U36: no | V36: 33.687206 | W36: standard | X36: ACT | Y36: 00-0031381
A37: 36 | B37: Michael Pittman | C37: PIT | D37: WR | E37: 31.07 | F37: 86.22 | G37: =ROUND(100*((1-SETTINGS!$B$2)*J37+SETTINGS!$B$2*Q37),2) | H37: 163.57812 | I37: 41.09 | J37: 0.3229 | K37: 95.786296 | L37: 245.8589 | M37: 20 | N37: 0.95052083 | O37: 0.49104256 | P37: 0.50895744 | Q37: 0.26181097 | R37: higher | S37: TRUE | T37: Questionable | U37: no | V37: 28.906822 | W37: standard | X37: ACT | Y37: 00-0036252
A38: 37 | B38: Courtland Sutton | C38: DEN | D38: WR | E38: 30.5 | F38: 86.09 | G38: =ROUND(100*((1-SETTINGS!$B$2)*J38+SETTINGS!$B$2*Q38),2) | H38: 162.54173 | I38: 40.06 | J38: 0.3148 | K38: 94.749911 | L38: 244.82251 | M38: 21 | N38: 0.94791667 | O38: 0.48727471 | P38: 0.51272529 | Q38: 0.26557882 | R38: higher | S38: FALSE | U38: no | V38: 30.894543 | W38: standard | X38: ACT | Y38: 00-0034348
A39: 38 | B39: James Cook | C39: BUF | D39: RB | E39: 29.63 | F39: 85.62 | G39: =ROUND(100*((1-SETTINGS!$B$2)*J39+SETTINGS!$B$2*Q39),2) | H39: 196.59144 | I39: 39.6 | J39: 0.3112 | K39: 127.43186 | L39: 311.55934 | M39: 9 | N39: 0.96190476 | O39: 0.566826 | P39: 0.433174 | Q39: 0.23661034 | R39: higher | S39: FALSE | U39: no | V39: 26.93553 | W39: standard | X39: ACT | Y39: 00-0037248
A40: 39 | B40: Breece Hall | C40: NYJ | D40: RB | E40: 29.06 | F40: 85.41 | G40: =ROUND(100*((1-SETTINGS!$B$2)*J40+SETTINGS!$B$2*Q40),2) | H40: 196.62306 | I40: 39.63 | J40: 0.3114 | K40: 127.46348 | L40: 311.59095 | M40: 8 | N40: 0.96666667 | O40: 0.59615961 | P40: 0.40384039 | Q40: 0.20727672 | R40: higher | S40: FALSE | U40: no | V40: 25.254454 | W40: standard | X40: ACT | Y40: 00-0038120
...

Sheet QB
A1: Rank | B1: Player | C1: Team | D1: Pos | E1: Overall Draft Score (replacement-adjusted) | F1: Position Draft Score (default weight) | G1: Custom-Weight Score (weight from SETTINGS) | H1: Projected 2026 Points | I1: Points Over Replacement | J1: Overall Value (points over replacement / max) | K1: Points P10 | L1: Points P90 | M1: Pos Points Rank | N1: Pos Points Percentile | O1: Missed-Time Injury Probability | P1: Healthy Probability | Q1: Healthy Probability vs Position Mean (+0.5) | R1: Injury Risk Band | S1: Current Injury Listing (screen date) | T1: Current Listing Status | U1: Rookie | V1: Age | W1: Points Model Confidence | X1: Roster Status (Aug 9) | Y1: Player ID
A2: 1 | B2: Josh Allen | C2: BUF | D2: QB | E2: 70.39 | F2: 91.32 | G2: =ROUND(100*((1-SETTINGS!$B$2)*N2+SETTINGS!$B$2*P2),2) | H2: 322.74206 | I2: 102.95 | J2: 0.809 | K2: 213.08296 | L2: 463.3179 | M2: 1 | N2: 1 | O2: 0.43420955 | P2: 0.56579045 | Q2: 0.28356424 | R2: higher | S2: FALSE | U2: no | V2: 30.281252 | W2: standard | X2: ACT | Y2: 00-0034857
A3: 2 | B3: Jared Goff | C3: DET | D3: QB | E3: 25.69 | F3: 90.84 | G3: =ROUND(100*((1-SETTINGS!$B$2)*N3+SETTINGS!$B$2*P3),2) | H3: 244.90236 | I3: 25.11 | J3: 0.1973 | K3: 135.24327 | L3: 385.4782 | M3: 8 | N3: 0.94117647 | O3: 0.22253456 | P3: 0.77746544 | Q3: 0.49523924 | R3: moderate | S3: FALSE | U3: no | V3: 31.882927 | W3: standard | X3: ACT | Y3: 00-0033106
A4: 3 | B4: Drake Maye | C4: NE | D4: QB | E4: 38.27 | F4: 90.36 | G4: =ROUND(100*((1-SETTINGS!$B$2)*N4+SETTINGS!$B$2*P4),2) | H4: 272.09196 | I4: 52.3 | J4: 0.411 | K4: 162.43286 | L4: 412.6678 | M4: 2 | N4: 0.99159664 | O4: 0.44824514 | P4: 0.55175486 | Q4: 0.26952865 | R4: higher | S4: FALSE | U4: no | V4: 24.005968 | W4: standard | X4: ACT | Y4: 00-0039851
A5: 4 | B5: Caleb Williams | C5: CHI | D5: QB | E5: 33.32 | F5: 89.49 | G5: =ROUND(100*((1-SETTINGS!$B$2)*N5+SETTINGS!$B$2*P5),2) | H5: 263.46877 | I5: 43.68 | J5: 0.3433 | K5: 153.80967 | L5: 404.04461 | M5: 4 | N5: 0.97478992 | O5: 0.42488997 | P5: 0.57511003 | Q5: 0.29288382 | R5: higher | S5: FALSE | U5: no | V5: 24.786272 | W5: standard | X5: ACT | Y5: 00-0039918
A6: 5 | B6: Jalen Hurts | C6: PHI | D6: QB | E6: 34.96 | F6: 89.23 | G6: =ROUND(100*((1-SETTINGS!$B$2)*N6+SETTINGS!$B$2*P6),2) | H6: 267.55492 | I6: 47.76 | J6: 0.3753 | K6: 157.89582 | L6: 408.13076 | M6: 3 | N6: 0.98319328 | O6: 0.47105394 | P6: 0.52894606 | Q6: 0.24671986 | R6: higher | S6: FALSE | U6: no | V6: 28.069023 | W6: standard | X6: ACT | Y6: 00-0036389
A7: 6 | B7: Bo Nix | C7: DEN | D7: QB | E7: 28.99 | F7: 88.94 | G7: =ROUND(100*((1-SETTINGS!$B$2)*N7+SETTINGS!$B$2*P7),2) | H7: 256.37092 | I7: 36.58 | J7: 0.2875 | K7: 146.71182 | L7: 396.94676 | M7: 5 | N7: 0.96638655 | O7: 0.41847222 | P7: 0.58152778 | Q7: 0.29930158 | R7: higher | S7: FALSE | U7: no | V7: 26.51663 | W7: standard | X7: ACT | Y7: 00-0039732
A8: 7 | B8: Justin Herbert | C8: LAC | D8: QB | E8: 24.27 | F8: 88.44 | G8: =ROUND(100*((1-SETTINGS!$B$2)*N8+SETTINGS!$B$2*P8),2) | H8: 248.61333 | I8: 28.82 | J8: 0.2265 | K8: 138.95423 | L8: 389.18917 | M8: 6 | N8: 0.95798319 | O8: 0.41010254 | P8: 0.58989746 | Q8: 0.30767125 | R8: higher | S8: FALSE | U8: no | V8: 28.47971 | W8: standard | X8: ACT | Y8: 00-0036355
A9: 8 | B9: Patrick Mahomes | C9: KC | D9: QB | E9: 17.19 | F9: 87.27 | G9: =ROUND(100*((1-SETTINGS!$B$2)*N9+SETTINGS!$B$2*P9),2) | H9: 235.99426 | I9: 16.2 | J9: 0.1273 | K9: 126.33516 | L9: 376.5701 | M9: 9 | N9: 0.93277311 | O9: 0.36752359 | P9: 0.63247641 | Q9: 0.35025021 | R9: higher | S9: TRUE | T9: Questionable | U9: no | V9: 30.957514 | W9: standard | X9: ACT | Y9: 00-0033873
A10: 9 | B10: Baker Mayfield | C10: TB | D10: QB | E10: 21.54 | F10: 86.99 | G10: =ROUND(100*((1-SETTINGS!$B$2)*N10+SETTINGS!$B$2*P10),2) | H10: 245.48501 | I10: 25.69 | J10: 0.2019 | K10: 135.82591 | L10: 386.06085 | M10: 7 | N10: 0.94957983 | O10: 0.44861377 | P10: 0.55138623 | Q10: 0.26916002 | R10: higher | S10: FALSE | U10: no | V10: 31.384628 | W10: standard | X10: ACT | Y10: 00-0034855
A11: 10 | B11: Matthew Stafford | C11: LA | D11: QB | E11: 8.71 | F11: 86.96 | G11: =ROUND(100*((1-SETTINGS!$B$2)*N11+SETTINGS!$B$2*P11),2) | H11: 219.79202 | I11: 0 | J11: 0 | K11: 110.13292 | L11: 360.36786 | M11: 12 | N11: 0.90756303 | O11: 0.28233285 | P11: 0.71766715 | Q11: 0.43544095 | R11: moderate | S11: FALSE | U11: no | V11: 38.566158 | W11: standard | X11: ACT | Y11: 00-0026498
A12: 11 | B12: Sam Darnold | C12: SEA | D12: QB | E12: 16.35 | F12: 86.6 | G12: =ROUND(100*((1-SETTINGS!$B$2)*N12+SETTINGS!$B$2*P12),2) | H12: 234.66665 | I12: 14.87 | J12: 0.1169 | K12: 125.00756 | L12: 375.2425 | M12: 10 | N12: 0.92436975 | O12: 0.36769669 | P12: 0.63230331 | Q12: 0.35007711 | R12: higher | S12: FALSE | U12: no | V12: 29.240847 | W12: standard | X12: ACT | Y12: 00-0034869
A13: 12 | B13: Trevor Lawrence | C13: JAX | D13: QB | E13: 8.76 | F13: 85.03 | G13: =ROUND(100*((1-SETTINGS!$B$2)*N13+SETTINGS!$B$2*P13),2) | H13: 224.00199 | I13: 4.21 | J13: 0.0331 | K13: 114.34289 | L13: 364.57783 | M13: 11 | N13: 0.91596639 | O13: 0.41239855 | P13: 0.58760145 | Q13: 0.30537525 | R13: higher | S13: FALSE | U13: no | V13: 26.905413 | W13: standard | X13: ACT | Y13: 00-0036971
A14: 13 | B14: Joe Burrow | C14: CIN | D14: QB | E14: 8.62 | F14: 83.51 | G14: =ROUND(100*((1-SETTINGS!$B$2)*N14+SETTINGS!$B$2*P14),2) | H14: 180.22304 | I14: -39.57 | J14: 0 | K14: 70.563941 | L14: 320.79888 | M14: 17 | N14: 0.86554622 | O14: 0.28680191 | P14: 0.71319809 | Q14: 0.43097188 | R14: moderate | S14: FALSE | U14: no | V14: 29.725456 | W14: standard | X14: ACT | Y14: 00-0036442
A15: 14 | B15: Jaxson Dart | C15: NYG | D15: QB | E15: 5.89 | F15: 83.46 | G15: =ROUND(100*((1-SETTINGS!$B$2)*N15+SETTINGS!$B$2*P15),2) | H15: 207.25922 | I15: -12.53 | J15: 0 | K15: 97.600127 | L15: 347.83506 | M15: 13 | N15: 0.89915966 | O15: 0.42344358 | P15: 0.57655642 | Q15: 0.29433021 | R15: higher | S15: FALSE | U15: no | V15: 23.305065 | W15: standard | X15: ACT | Y15: 00-0040691
A16: 15 | B16: Jordan Love | C16: GB | D16: QB | E16: 5.83 | F16: 82.06 | G16: =ROUND(100*((1-SETTINGS!$B$2)*N16+SETTINGS!$B$2*P16),2) | H16: 196.14107 | I16: -23.65 | J16: 0 | K16: 86.481977 | L16: 336.71691 | M16: 15 | N16: 0.88235294 | O16: 0.42616504 | P16: 0.57383496 | Q16: 0.29160875 | R16: higher | S16: FALSE | U16: no | V16: 27.830824 | W16: standard | X16: ACT | Y16: 00-0036264
A17: 16 | B17: Lamar Jackson | C17: BAL | D17: QB | E17: 5.06 | F17: 81.97 | G17: =ROUND(100*((1-SETTINGS!$B$2)*N17+SETTINGS!$B$2*P17),2) | H17: 204.22869 | I17: -15.56 | J17: 0 | K17: 94.56959 | L17: 344.80453 | M17: 14 | N17: 0.8907563 | O17: 0.46477309 | P17: 0.53522691 | Q17: 0.25300071 | R17: higher | S17: FALSE | U17: no | V17: 29.648794 | W17: standard | X17: ACT | Y17: 00-0034796
A18: 17 | B18: Cam Ward | C18: TEN | D18: QB | E18: 6.03 | F18: 81.59 | G18: =ROUND(100*((1-SETTINGS!$B$2)*N18+SETTINGS!$B$2*P18),2) | H18: 191.05727 | I18: -28.73 | J18: 0 | K18: 81.398176 | L18: 331.63311 | M18: 16 | N18: 0.87394958 | O18: 0.41605384 | P18: 0.58394616 | Q18: 0.30171995 | R18: higher | S18: FALSE | U18: no | V18: 24.271545 | W18: standard | X18: ACT | Y18: 00-0040676
A19: 18 | B19: Dak Prescott | C19: DAL | D19: QB | E19: 7.37 | F19: 80.91 | G19: =ROUND(100*((1-SETTINGS!$B$2)*N19+SETTINGS!$B$2*P19),2) | H19: 176.68635 | I19: -43.11 | J19: 0 | K19: 67.027257 | L19: 317.26219 | M19: 19 | N19: 0.8487395 | O19: 0.3492731 | P19: 0.6507269 | Q19: 0.3685007 | R19: moderate | S19: FALSE | U19: no | V19: 33.093082 | W19: standard | X19: ACT | Y19: 00-0033077
A20: 19 | B20: Tyler Shough | C20: NO | D20: QB | E20: 7.03 | F20: 79.9 | G20: =ROUND(100*((1-SETTINGS!$B$2)*N20+SETTINGS!$B$2*P20),2) | H20: 169.78443 | I20: -50.01 | J20: 0 | K20: 60.125335 | L20: 310.36027 | M20: 20 | N20: 0.84033613 | O20: 0.36619745 | P20: 0.63380255 | Q20: 0.35157634 | R20: higher | S20: FALSE | U20: no | V20: 26.927315 | W20: standard | X20: ACT | Y20: 00-0040743
A21: 20 | B21: Aaron Rodgers | C21: PIT | D21: QB | E21: 7.34 | F21: 79.54 | G21: =ROUND(100*((1-SETTINGS!$B$2)*N21+SETTINGS!$B$2*P21),2) | H21: 162.59147 | I21: -57.2 | J21: 0 | K21: 52.932375 | L21: 303.16731 | M21: 21 | N21: 0.83193277 | O21: 0.3508306 | P21: 0.6491694 | Q21: 0.3669432 | R21: higher | S21: FALSE | U21: no | V21: 42.74968 | W21: standard | X21: ACT | Y21: 00-0023459
... A30: 29 | B30: Bryce Young | C30: CAR | D30: QB | E30: 3.84 | F30: 75.36 | G30: =ROUND(100*((1-SETTINGS!$B$2)*N30+SETTINGS!$B$2*P30),2) | H30: 161.513 | I30: -58.28 | J30: 0 | K30: 51.853906 | L30: 302.08884 | M30: 22 | N30: 0.82352941 | O30: 0.52587438 | P30: 0.47412562 | Q30: 0.19189941 | R30: higher | S30: FALSE | U30: no | V30: 25.103868 | W30: standard | X30: ACT | Y30: 00-0039150
A31: 30 | B31: Tua Tagovailoa | C31: ATL | D31: QB | E31: 8.53 | F31: 74.68 | G31: =ROUND(100*((1-SETTINGS!$B$2)*N31+SETTINGS!$B$2*P31),2) | H31: 114.61954 | I31: -105.17 | J31: 0 | K31: 4.9604442 | L31: 255.19538 | M31: 30 | N31: 0.75630252 | O31: 0.29103142 | P31: 0.70896858 | Q31: 0.42674238 | R31: moderate | S31: TRUE | T31: Questionable | U31: no | V31: 28.501612 | W31: standard | X31: ACT | Y31: 00-0036212
A32: 31 | B32: Justin Fields | C32: KC | D32: QB | E32: 5.8 | F32: 73.3 | G32: =ROUND(100*((1-SETTINGS!$B$2)*N32+SETTINGS!$B$2*P32),2) | H32: 120.25003 | I32: -99.54 | J32: 0 | K32: 10.590934 | L32: 260.82587 | M32: 28 | N32: 0.77310924 | O32: 0.42757457 | P32: 0.57242543 | Q32: 0.29019923 | R32: higher | S32: FALSE | U32: no | V32: 27.494062 | W32: standard | X32: ACT | Y32: 00-0036945
A33: 32 | B33: Mac Jones | C33: SF | D33: QB | E33: 9.01 | F33: 72.47 | G33: =ROUND(100*((1-SETTINGS!$B$2)*N33+SETTINGS!$B$2*P33),2) | H33: 85.655328 | I33: -134.14 | J33: 0 | K33: 0 | L33: 226.23117 | M33: 34 | N33: 0.72268908 | O33: 0.26712335 | P33: 0.73287665 | Q33: 0.45065044 | R33: moderate | S33: FALSE | U33: no | V33: 27.989624 | W33: standard | X33: ACT | Y33: 00-0036972
A34: 33 | B34: Jayden Daniels | C34: WAS | D34: QB | E34: 7.22 | F34: 72.02 | G34: =ROUND(100*((1-SETTINGS!$B$2)*N34+SETTINGS!$B$2*P34),2) | H34: 93.543455 | I34: -126.25 | J34: 0 | K34: 0 | L34: 234.1193 | M34: 32 | N34: 0.7394958 | O34: 0.35692143 | P34: 0.64307857 | Q34: 0.36085237 | R34: higher | S34: FALSE | U34: no | V34: 25.70347 | W34: standard | X34: ACT | Y34: 00-0039910
A35: 34 | B35: Michael Penix Jr. | C35: ATL | D35: QB | E35: 8.33 | F35: 71.11 | G35: =ROUND(100*((1-SETTINGS!$B$2)*N35+SETTINGS!$B$2*P35),2) | H35: 82.425923 | I35: -137.37 | J35: 0 | K35: 0 | L35: 223.00176 | M35: 35 | N35: 0.71428571 | O35: 0.30147154 | P35: 0.69852846 | Q35: 0.41630226 | R35: moderate | S35: TRUE | T35: Questionable | U35: no | V35: 26.316763 | W35: standard | X35: ACT | Y35: 00-0039917
A36: 35 | B36: J.J. McCarthy | C36: MIN | D36: QB | E36: 6.64 | F36: 70.77 | G36: =ROUND(100*((1-SETTINGS!$B$2)*N36+SETTINGS!$B$2*P36),2) | H36: 89.648551 | I36: -130.14 | J36: 0 | K36: 0 | L36: 230.22439 | M36: 33 | N36: 0.73109244 | O36: 0.38596822 | P36: 0.61403178 | Q36: 0.33180557 | R36: higher | S36: FALSE | U36: no | V36: 23.614449 | W36: standard | X36: ACT | Y36: 00-0039923
A37: 36 | B37: Riley Leonard | C37: IND | D37: QB | E37: 10.56 | F37: 70.65 | G37: =ROUND(100*((1-SETTINGS!$B$2)*N37+SETTINGS!$B$2*P37),2) | H37: 68.060366 | I37: -151.73 | J37: 0 | K37: 0 | L37: 208.63621 | M37: 39 | N37: 0.68067227 | O37: 0.19001409 | P37: 0.80998591 | Q37: 0.5277597 | R37: lower | S37: FALSE | U37: no | V37: 23.967638 | W37: standard | X37: ACT | Y37: 00-0040206
A38: 37 | B38: Quinn Ewers | C38: MIA | D38: QB | E38: 9.1 | F38: 69.87 | G38: =ROUND(100*((1-SETTINGS!$B$2)*N38+SETTINGS!$B$2*P38),2) | H38: 71.707461 | I38: -148.08 | J38: 0 | K38: 0 | L38: 212.2833 | M38: 38 | N38: 0.68907563 | O38: 0.26297702 | P38: 0.73702298 | Q38: 0.45479677 | R38: moderate | S38: FALSE | U38: no | V38: 23.4666 | W38: standard | X38: ACT | Y38: 00-0040234
A39: 38 | B39: Marcus Mariota | C39: WAS | D39: QB | E39: 7.44 | F39: 69.55 | G39: =ROUND(100*((1-SETTINGS!$B$2)*N39+SETTINGS!$B$2*P39),2) | H39: 80.64105 | I39: -139.15 | J39: 0 | K39: 0 | L39: 221.21689 | M39: 36 | N39: 0.70588235 | O39: 0.34592804 | P39: 0.65407196 | Q39: 0.37184576 | R39: moderate | S39: FALSE | U39: no | V39: 32.838455 | W39: standard | X39: ACT | Y39: 00-0032268
A40: 39 | B40: Joe Flacco | C40: CIN | D40: QB | E40: 8.08 | F40: 69.52 | G40: =ROUND(100*((1-SETTINGS!$B$2)*N40+SETTINGS!$B$2*P40),2) | H40: 79.285153 | I40: -140.51 | J40: 0 | K40: 0 | L40: 219.86099 | M40: 37 | N40: 0.69747899 | O40: 0.31371272 | P40: 0.68628728 | Q40: 0.40406108 | R40: moderate | S40: FALSE | U40: no | V40: 41.624401 | W40: standard | X40: ACT | Y40: 00-0026158
A41: 40 | B41: Carson Wentz | C41: MIN | D41: QB | E41: 9.49 | F41: 68.92 | G41: =ROUND(100*((1-SETTINGS!$B$2)*N41+SETTINGS!$B$2*P41),2) | H41: 65.648848 | I41: -154.14 | J41: 0 | K41: 0 | L41: 206.22469 | M41: 40 | N41: 0.67226891 | O41: 0.24331258 | P41: 0.75668742 | Q41: 0.47446122 | R41: moderate | S41: FALSE | U41: no | V41: 33.67078 | W41: standard | X41: ACT | Y41: 00-0032950
A42: 41 | B42: Dillon Gabriel | C42: CLE | D42: QB | E42: 9.06 | F42: 67.82 | G42: =ROUND(100*((1-SETTINGS!$B$2)*N42+SETTINGS!$B$2*P42),2) | H42: 64.863561 | I42: -154.93 | J42: 0 | K42: 0 | L42: 205.4394 | M42: 41 | N42: 0.66386555 | O42: 0.26463087 | P42: 0.73536913 | Q42: 0.45314292 | R42: moderate | S42: FALSE | U42: no | V42: 25.676092 | W42: standard | X42: ACT | Y42: 00-0040704
A43: 42 | B43: Jameis Winston | C43: NYG | D43: QB | E43: 9.99 | F43: 66.72 | G43: =ROUND(100*((1-SETTINGS!$B$2)*N43+SETTINGS!$B$2*P43),2) | H43: 44.639282 | I43: -175.15 | J43: 0 | K43: 9.9978768 | L43: 89.01642 | M43: 44 | N43: 0.63865546 | O43: 0.21846044 | P43: 0.78153956 | Q43: 0.49931336 | R43: moderate | S43: FALSE | U43: no | V43: 32.652279 | W43: standard | X43: ACT | Y43: 00-0031503
A44: 43 | B44: Anthony Richardson | C44: IND | D44: QB | E44: 8.07 | F44: 66.16 | G44: =ROUND(100*((1-SETTINGS!$B$2)*N44+SETTINGS!$B$2*P44),2) | H44: 61.706992 | I44: -158.09 | J44: 0 | K44: 0 | L44: 202.28283 | M44: 42 | N44: 0.65546218 | O44: 0.31403754 | P44: 0.68596246 | Q44: 0.40373626 | R44: moderate | S44: FALSE | U44: no | V44: 24.279758 | W44: standard | X44: ACT | Y44: 00-0039164
A45: 44 | B45: Davis Mills | C45: HOU | D45: QB | E45: 10.09 | F45: 66.15 | G45: =ROUND(100*((1-SETTINGS!$B$2)*N45+SETTINGS!$B$2*P45),2) | H45: 44.548753 | I45: -175.24 | J45: 0 | K45: 9.9073478 | L45: 88.925891 | M45: 45 | N45: 0.6302521 | O45: 0.21351218 | P45: 0.78648782 | Q45: 0.50426162 | R45: moderate | S45: FALSE | U45: no | V45: 27.86368 | W45: standard | X45: ACT | Y45: 00-0036898
A46: 45 | B46: Spencer Rattler | C46: NO | D46: QB | E46: 8.72 | F46: 66.13 | G46: =ROUND(100*((1-SETTINGS!$B$2)*N46+SETTINGS!$B$2*P46),2) | H46: 56.840522 | I46: -162.95 | J46: 0 | K46: 0 | L46: 197.41636 | M46: 43 | N46: 0.64705882 | O46: 0.28159948 | P46: 0.71840052 | Q46: 0.43617431 | R46: moderate | S46: FALSE | U46: no | V46: 25.925241 | W46: standard | X46: ACT | Y46: 00-0039376
A47: 46 | B47: Tyrod Taylor | C47: GB | D47: QB | E47: 9.39 | F47: 64.78 | G47: =ROUND(100*((1-SETTINGS!$B$2)*N47+SETTINGS!$B$2*P47),2) | H47: 43.682119 | I47: -176.11 | J47: 0 | K47: 9.0407133 | L47: 88.059257 | M47: 46 | N47: 0.62184874 | O47: 0.24840789 | P47: 0.75159211 | Q47: 0.46936591 | R47: moderate | S47: FALSE | U47: no | V47: 37.079475 | W47: standard | X47: ACT | Y47: 00-0028118
... A56: 55 | B56: Mason Rudolph | C56: PIT | D56: QB | E56: 11.36 | F56: 60.03 | G56: =ROUND(100*((1-SETTINGS!$B$2)*N56+SETTINGS!$B$2*P56),2) | H56: 27.041444 | I56: -192.75 | J56: 0 | K56: 0 | L56: 71.418582 | M56: 56 | N56: 0.53781513 | O56: 0.14953916 | P56: 0.85046084 | Q56: 0.56823463 | R56: lower | S56: FALSE | U56: no | V56: 31.127264 | W56: standard | X56: ACT | Y56: 00-0034771
...

Sheet RB
A1: Rank | B1: Player | C1: Team | D1: Pos | E1: Overall Draft Score (replacement-adjusted) | F1: Position Draft Score (default weight) | G1: Custom-Weight Score (weight from SETTINGS) | H1: Projected 2026 Points | I1: Points Over Replacement | J1: Overall Value (points over replacement / max) | K1: Points P10 | L1: Points P90 | M1: Pos Points Rank | N1: Pos Points Percentile | O1: Missed-Time Injury Probability | P1: Healthy Probability | Q1: Healthy Probability vs Position Mean (+0.5) | R1: Injury Risk Band | S1: Current Injury Listing (screen date) | T1: Current Listing Status | U1: Rookie | V1: Age | W1: Points Model Confidence | X1: Roster Status (Aug 9) | Y1: Player ID
A2: 1 | B2: Derrick Henry | C2: BAL | D2: RB | E2: 52.62 | F2: 89.34 | G2: =ROUND(100*((1-SETTINGS!$B$2)*N2+SETTINGS!$B$2*P2),2) | H2: 230.26795 | I2: 73.27 | J2: 0.5758 | K2: 161.10837 | L2: 345.23584 | M2: 4 | N2: 0.98571429 | O2: 0.47582579 | P2: 0.52417421 | Q2: 0.32761055 | R2: higher | S2: FALSE | U2: no | V2: 32.657753 | W2: standard | X2: ACT | Y2: 00-0032764
A3: 2 | B3: Bijan Robinson | C3: ATL | D3: RB | E3: 72.02 | F3: 88.24 | G3: =ROUND(100*((1-SETTINGS!$B$2)*N3+SETTINGS!$B$2*P3),2) | H3: 264.68583 | I3: 107.69 | J3: 0.8463 | K3: 195.52625 | L3: 379.65372 | M3: 1 | N3: 1 | O3: 0.58776347 | P3: 0.41223653 | Q3: 0.21567287 | R3: higher | S3: FALSE | U3: no | V3: 24.586405 | W3: standard | X3: ACT | Y3: 00-0038542
A4: 3 | B4: Jahmyr Gibbs | C4: DET | D4: RB | E4: 56.76 | F4: 87.83 | G4: =ROUND(100*((1-SETTINGS!$B$2)*N4+SETTINGS!$B$2*P4),2) | H4: 240.4644 | I4: 83.47 | J4: 0.656 | K4: 171.30482 | L4: 355.4323 | M4: 2 | N4: 0.9952381 | O4: 0.5893529 | P4: 0.4106471 | Q4: 0.21408344 | R4: higher | S4: TRUE | T4: Questionable | U4: no | V4: 24.452248 | W4: standard | X4: ACT | Y4: 00-0039139
A5: 4 | B5: Kyren Williams | C5: LA | D5: RB | E5: 31.7 | F5: 87.72 | G5: =ROUND(100*((1-SETTINGS!$B$2)*N5+SETTINGS!$B$2*P5),2) | H5: 197.75366 | I5: 40.76 | J5: 0.3203 | K5: 128.59408 | L5: 312.72156 | M5: 7 | N5: 0.97142857 | O5: 0.49950467 | P5: 0.50049533 | Q5: 0.30393166 | R5: higher | S5: FALSE | U5: no | V5: 26.015593 | W5: standard | X5: ACT | Y5: 00-0037840
A6: 5 | B6: Ashton Jeanty | C6: LV | D6: RB | E6: 46.99 | F6: 87.67 | G6: =ROUND(100*((1-SETTINGS!$B$2)*N6+SETTINGS!$B$2*P6),2) | H6: 223.37205 | I6: 66.38 | J6: 0.5217 | K6: 154.21247 | L6: 338.33995 | M6: 5 | N6: 0.98095238 | O6: 0.54054458 | P6: 0.45945542 | Q6: 0.26289176 | R6: higher | S6: FALSE | U6: no | V6: 22.749269 | W6: standard | X6: ACT | Y6: 00-0040122
A7: 6 | B7: De'Von Achane | C7: MIA | D7: RB | E7: 51.29 | F7: 87.47 | G7: =ROUND(100*((1-SETTINGS!$B$2)*N7+SETTINGS!$B$2*P7),2) | H7: 231.74679 | I7: 74.75 | J7: 0.5874 | K7: 162.58721 | L7: 346.71469 | M7: 3 | N7: 0.99047619 | O7: 0.58838759 | P7: 0.41161241 | Q7: 0.21504875 | R7: higher | S7: FALSE | U7: no | V7: 24.884836 | W7: standard | X7: ACT | Y7: 00-0039040
A8: 7 | B8: Chase Brown | C8: CIN | D8: RB | E8: 41.07 | F8: 87.19 | G8: =ROUND(100*((1-SETTINGS!$B$2)*N8+SETTINGS!$B$2*P8),2) | H8: 214.10578 | I8: 57.11 | J8: 0.4488 | K8: 144.9462 | L8: 329.07368 | M8: 6 | N8: 0.97619048 | O8: 0.54521446 | P8: 0.45478554 | Q8: 0.25822187 | R8: higher | S8: FALSE | U8: no | V8: 26.448181 | W8: standard | X8: ACT | Y8: 00-0038597
A9: 8 | B9: D'Andre Swift | C9: CHI | D9: RB | E9: 27.07 | F9: 86.1 | G9: =ROUND(100*((1-SETTINGS!$B$2)*N9+SETTINGS!$B$2*P9),2) | H9: 191.17046 | I9: 34.17 | J9: 0.2685 | K9: 122.01088 | L9: 306.13835 | M9: 10 | N9: 0.95714286 | O9: 0.52381258 | P9: 0.47618742 | Q9: 0.27962376 | R9: higher | S9: FALSE | U9: no | V9: 27.630957 | W9: standard | X9: ACT | Y9: 00-0036275
A10: 9 | B10: James Cook | C10: BUF | D10: RB | E10: 29.63 | F10: 85.62 | G10: =ROUND(100*((1-SETTINGS!$B$2)*N10+SETTINGS!$B$2*P10),2) | H10: 196.59144 | I10: 39.6 | J10: 0.3112 | K10: 127.43186 | L10: 311.55934 | M10: 9 | N10: 0.96190476 | O10: 0.566826 | P10: 0.433174 | Q10: 0.23661034 | R10: higher | S10: FALSE | U10: no | V10: 26.93553 | W10: standard | X10: ACT | Y10: 00-0037248
A11: 10 | B11: Breece Hall | C11: NYJ | D11: RB | E11: 29.06 | F11: 85.41 | G11: =ROUND(100*((1-SETTINGS!$B$2)*N11+SETTINGS!$B$2*P11),2) | H11: 196.62306 | I11: 39.63 | J11: 0.3114 | K11: 127.46348 | L11: 311.59095 | M11: 8 | N11: 0.96666667 | O11: 0.59615961 | P11: 0.40384039 | Q11: 0.20727672 | R11: higher | S11: FALSE | U11: no | V11: 25.254454 | W11: standard | X11: ACT | Y11: 00-0038120
A12: 11 | B12: TreVeyon Henderson | C12: NE | D12: RB | E12: 17.63 | F12: 84.94 | G12: =ROUND(100*((1-SETTINGS!$B$2)*N12+SETTINGS!$B$2*P12),2) | H12: 176.16169 | I12: 19.17 | J12: 0.1506 | K12: 107.00211 | L12: 291.12959 | M12: 13 | N12: 0.94285714 | O12: 0.52434617 | P12: 0.47565383 | Q12: 0.27909017 | R12: higher | S12: FALSE | U12: no | V12: 23.860859 | W12: standard | X12: ACT | Y12: 00-0040734
A13: 12 | B13: Christian McCaffrey | C13: SF | D13: RB | E13: 23.61 | F13: 84.47 | G13: =ROUND(100*((1-SETTINGS!$B$2)*N13+SETTINGS!$B$2*P13),2) | H13: 187.63536 | I13: 30.64 | J13: 0.2408 | K13: 118.47578 | L13: 302.60325 | M13: 11 | N13: 0.95238095 | O13: 0.58589425 | P13: 0.41410575 | Q13: 0.21754209 | R13: higher | S13: TRUE | T13: Questionable | U13: no | V13: 30.234707 | W13: standard | X13: ACT | Y13: 00-0033280
A14: 13 | B14: Saquon Barkley | C14: PHI | D14: RB | E14: 17.06 | F14: 84.3 | G14: =ROUND(100*((1-SETTINGS!$B$2)*N14+SETTINGS!$B$2*P14),2) | H14: 176.87906 | I14: 19.88 | J14: 0.1562 | K14: 107.71948 | L14: 291.84696 | M14: 12 | N14: 0.94761905 | O14: 0.57533157 | P14: 0.42466843 | Q14: 0.22810477 | R14: higher | S14: FALSE | U14: no | V14: 29.558445 | W14: standard | X14: ACT | Y14: 00-0034844
A15: 14 | B15: RJ Harvey | C15: DEN | D15: RB | E15: 14.83 | F15: 84.1 | G15: =ROUND(100*((1-SETTINGS!$B$2)*N15+SETTINGS!$B$2*P15),2) | H15: 171.83337 | I15: 14.84 | J15: 0.1166 | K15: 102.67379 | L15: 286.80127 | M15: 15 | N15: 0.93333333 | O15: 0.52813255 | P15: 0.47186745 | Q15: 0.27530379 | R15: higher | S15: FALSE | U15: no | V15: 25.572052 | W15: standard | X15: ACT | Y15: 00-0040730
A16: 15 | B16: Kenneth Walker III | C16: KC | D16: RB | E16: 15.81 | F16: 83.45 | G16: =ROUND(100*((1-SETTINGS!$B$2)*N16+SETTINGS!$B$2*P16),2) | H16: 175.02581 | I16: 18.03 | J16: 0.1417 | K16: 105.86623 | L16: 289.99371 | M16: 14 | N16: 0.93809524 | O16: 0.57975096 | P16: 0.42024904 | Q16: 0.22368538 | R16: higher | S16: FALSE | U16: no | V16: 25.865007 | W16: standard | X16: ACT | Y16: 00-0038134
A17: 16 | B17: Jaylen Warren | C17: PIT | D17: RB | E17: 13.92 | F17: 83.43 | G17: =ROUND(100*((1-SETTINGS!$B$2)*N17+SETTINGS!$B$2*P17),2) | H17: 170.84951 | I17: 13.85 | J17: 0.1088 | K17: 101.68993 | L17: 285.81741 | M17: 16 | N17: 0.92857143 | O17: 0.54264202 | P17: 0.45735798 | Q17: 0.26079432 | R17: higher | S17: FALSE | U17: no | V17: 27.833563 | W17: standard | X17: ACT | Y17: 00-0037228
A18: 17 | B18: Tony Pollard | C18: TEN | D18: RB | E18: 13.89 | F18: 83.22 | G18: =ROUND(100*((1-SETTINGS!$B$2)*N18+SETTINGS!$B$2*P18),2) | H18: 170.52083 | I18: 13.53 | J18: 0.1063 | K18: 101.36125 | L18: 285.48873 | M18: 17 | N18: 0.92380952 | O18: 0.53399148 | P18: 0.46600852 | Q18: 0.26944486 | R18: higher | S18: FALSE | U18: no | V18: 29.339411 | W18: standard | X18: ACT | Y18: 00-0035261
A19: 18 | B19: Tyrone Tracy Jr. | C19: NYG | D19: RB | E19: 8.86 | F19: 82.28 | G19: =ROUND(100*((1-SETTINGS!$B$2)*N19+SETTINGS!$B$2*P19),2) | H19: 162.20419 | I19: 5.21 | J19: 0.0409 | K19: 93.044604 | L19: 277.17208 | M19: 20 | N19: 0.90952381 | O19: 0.5238792 | P19: 0.4761208 | Q19: 0.27955714 | R19: higher | S19: FALSE | U19: no | V19: 26.773993 | W19: standard | X19: ACT | Y19: 00-0039384
A20: 19 | B20: Travis Etienne | C20: NO | D20: RB | E20: 11.97 | F20: 81.76 | G20: =ROUND(100*((1-SETTINGS!$B$2)*N20+SETTINGS!$B$2*P20),2) | H20: 169.18909 | I20: 12.19 | J20: 0.0958 | K20: 100.02951 | L20: 284.15699 | M20: 18 | N20: 0.91904762 | O20: 0.58812969 | P20: 0.41187031 | Q20: 0.21530665 | R20: higher | S20: FALSE | U20: no | V20: 27.598103 | W20: standard | X20: ACT | Y20: 00-0036973
A21: 20 | B21: Josh Jacobs | C21: GB | D21: RB | E21: 7.38 | F21: 81.65 | G21: =ROUND(100*((1-SETTINGS!$B$2)*N21+SETTINGS!$B$2*P21),2) | H21: 160.24005 | I21: 3.24 | J21: 0.0255 | K21: 91.080464 | L21: 275.20794 | M21: 21 | N21: 0.9047619 | O21: 0.53634448 | P21: 0.46365552 | Q21: 0.26709185 | R21: higher | S21: TRUE | T21: Questionable | U21: no | V21: 28.553633 | W21: standard | X21: ACT | Y21: 00-0035700
A22: 21 | B22: Bucky Irving | C22: TB | D22: RB | E22: 5.78 | F22: 81.09 | G22: =ROUND(100*((1-SETTINGS!$B$2)*N22+SETTINGS!$B$2*P22),2) | H22: 157.39499 | I22: 0.4 | J22: 0.0031 | K22: 88.235409 | L22: 272.36289 | M22: 23 | N22: 0.8952381 | O22: 0.52666092 | P22: 0.47333908 | Q22: 0.27677541 | R22: higher | S22: FALSE | U22: no | V22: 24.036085 | W22: standard | X22: ACT | Y22: 00-0039361
A23: 22 | B23: Jonathan Taylor | C23: IND | D23: RB | E23: 7.79 | F23: 81.04 | G23: =ROUND(100*((1-SETTINGS!$B$2)*N23+SETTINGS!$B$2*P23),2) | H23: 163.09199 | I23: 6.1 | J23: 0.0479 | K23: 93.932413 | L23: 278.05989 | M23: 19 | N23: 0.91428571 | O23: 0.60536284 | P23: 0.39463716 | Q23: 0.19807349 | R23: higher | S23: FALSE | U23: no | V23: 27.617268 | W23: standard | X23: ACT | Y23: 00-0036223
A24: 23 | B24: Rico Dowdle | C24: PIT | D24: RB | E24: 6.46 | F24: 80.7 | G24: =ROUND(100*((1-SETTINGS!$B$2)*N24+SETTINGS!$B$2*P24),2) | H24: 159.68369 | I24: 2.69 | J24: 0.0211 | K24: 90.52411 | L24: 274.65159 | M24: 22 | N24: 0.9 | O24: 0.56484874 | P24: 0.43515126 | Q24: 0.2385876 | R24: higher | S24: FALSE | U24: no | V24: 28.216869 | W24: standard | X24: ACT | Y24: 00-0036139
A25: 24 | B25: Woody Marks | C25: HOU | D25: RB | E25: 5.33 | F25: 80.12 | G25: =ROUND(100*((1-SETTINGS!$B$2)*N25+SETTINGS!$B$2*P25),2) | H25: 155.04385 | I25: -1.95 | J25: 0 | K25: 85.884265 | L25: 270.01174 | M25: 25 | N25: 0.88571429 | O25: 0.53674186 | P25: 0.46325814 | Q25: 0.26669448 | R25: higher | S25: FALSE | U25: no | V25: 25.673353 | W25: standard | X25: ACT | Y25: 00-0040583
A26: 25 | B26: Rachaad White | C26: WAS | D26: RB | E26: 7.23 | F26: 80.12 | G26: =ROUND(100*((1-SETTINGS!$B$2)*N26+SETTINGS!$B$2*P26),2) | H26: 126.17494 | I26: -30.82 | J26: 0 | K26: 57.01536 | L26: 241.14284 | M26: 30 | N26: 0.86190476 | O26: 0.44185351 | P26: 0.55814649 | Q26: 0.36158283 | R26: higher | S26: FALSE | U26: no | V26: 27.636433 | W26: standard | X26: ACT | Y26: 00-0037256
A27: 26 | B27: Kyle Monangai | C27: CHI | D27: RB | E27: 5.61 | F27: 79.64 | G27: =ROUND(100*((1-SETTINGS!$B$2)*N27+SETTINGS!$B$2*P27),2) | H27: 144.85013 | I27: -12.15 | J27: 0 | K27: 75.690551 | L27: 259.81803 | M27: 27 | N27: 0.87619048 | O27: 0.52278899 | P27: 0.47721101 | Q27: 0.28064735 | R27: higher | S27: FALSE | U27: no | V27: 24.238691 | W27: standard | X27: ACT | Y27: 00-0040236
A28: 27 | B28: Zach Charbonnet | C28: SEA | D28: RB | E28: 7.3 | F28: 79.42 | G28: =ROUND(100*((1-SETTINGS!$B$2)*N28+SETTINGS!$B$2*P28),2) | H28: 119.81819 | I28: -37.18 | J28: 0 | K28: 50.658613 | L28: 234.78609 | M28: 32 | N28: 0.85238095 | O28: 0.43839235 | P28: 0.56160765 | Q28: 0.36504399 | R28: higher | S28: TRUE | T28: Out | U28: no | V28: 25.645975 | W28: standard | X28: ACT | Y28: 00-0039165
A29: 28 | B29: Javonte Williams | C29: DAL | D29: RB | E29: 4.23 | F29: 79.4 | G29: =ROUND(100*((1-SETTINGS!$B$2)*N29+SETTINGS!$B$2*P29),2) | H29: 156.99572 | I29: 0 | J29: 0 | K29: 87.836136 | L29: 271.96361 | M29: 24 | N29: 0.89047619 | O29: 0.59214692 | P29: 0.40785308 | Q29: 0.21128941 | R29: higher | S29: FALSE | U29: no | V29: 26.352354 | W29: standard | X29: ACT | Y29: 00-0036997
A30: 29 | B30: Kenneth Gainwell | C30: TB | D30: RB | E30: 5.75 | F30: 79.4 | G30: =ROUND(100*((1-SETTINGS!$B$2)*N30+SETTINGS!$B$2*P30),2) | H30: 141.92959 | I30: -15.07 | J30: 0 | K30: 72.770004 | L30: 256.89748 | M30: 28 | N30: 0.87142857 | O30: 0.5159132 | P30: 0.4840868 | Q30: 0.28752314 | R30: higher | S30: FALSE | U30: no | V30: 27.469421 | W30: standard | X30: ACT | Y30: 00-0036919
A31: 30 | B31: Quinshon Judkins | C31: CLE | D31: RB | E31: 4.33 | F31: 78.74 | G31: =ROUND(100*((1-SETTINGS!$B$2)*N31+SETTINGS!$B$2*P31),2) | H31: 144.96214 | I31: -12.03 | J31: 0 | K31: 75.802555 | L31: 259.93003 | M31: 26 | N31: 0.88095238 | O31: 0.58678229 | P31: 0.41321771 | Q31: 0.21665405 | R31: higher | S31: FALSE | U31: no | V31: 22.842358 | W31: standard | X31: ACT | Y31: 00-0040784
A32: 31 | B32: Blake Corum | C32: LA | D32: RB | E32: 7.03 | F32: 78.39 | G32: =ROUND(100*((1-SETTINGS!$B$2)*N32+SETTINGS!$B$2*P32),2) | H32: 118.67241 | I32: -38.32 | J32: 0 | K32: 49.512824 | L32: 233.6403 | M32: 34 | N32: 0.84285714 | O32: 0.45178913 | P32: 0.54821087 | Q32: 0.35164721 | R32: higher | S32: FALSE | U32: no | V32: 25.766443 | W32: standard | X32: ACT | Y32: 00-0039738
A33: 32 | B33: Rhamondre Stevenson | C33: NE | D33: RB | E33: 5.04 | F33: 78.31 | G33: =ROUND(100*((1-SETTINGS!$B$2)*N33+SETTINGS!$B$2*P33),2) | H33: 128.98762 | I33: -28.01 | J33: 0 | K33: 59.828037 | L33: 243.95551 | M33: 29 | N33: 0.86666667 | O33: 0.55140531 | P33: 0.44859469 | Q33: 0.25203103 | R33: higher | S33: FALSE | U33: no | V33: 28.520777 | W33: standard | X33: ACT | Y33: 00-0036875
A34: 33 | B34: Jacory Croskey-Merritt | C34: WAS | D34: RB | E34: 6.53 | F34: 78.27 | G34: =ROUND(100*((1-SETTINGS!$B$2)*N34+SETTINGS!$B$2*P34),2) | H34: 118.84074 | I34: -38.15 | J34: 0 | K34: 49.681157 | L34: 233.80863 | M34: 33 | N34: 0.84761905 | O34: 0.4769794 | P34: 0.5230206 | Q34: 0.32645694 | R34: higher | S34: FALSE | U34: no | V34: 25.388611 | W34: standard | X34: ACT | Y34: 00-0040242
A35: 34 | B35: Omarion Hampton | C35: LAC | D35: RB | E35: 4.81 | F35: 77.31 | G35: =ROUND(100*((1-SETTINGS!$B$2)*N35+SETTINGS!$B$2*P35),2) | H35: 123.61245 | I35: -33.38 | J35: 0 | K35: 54.452864 | L35: 238.58034 | M35: 31 | N35: 0.85714286 | O35: 0.56291143 | P35: 0.43708857 | Q35: 0.24052491 | R35: higher | S35: FALSE | U35: no | V35: 23.463863 | W35: standard | X35: ACT | Y35: 00-0040666
A36: 35 | B36: Aaron Jones | C36: MIN | D36: RB | E36: 6.58 | F36: 77.18 | G36: =ROUND(100*((1-SETTINGS!$B$2)*N36+SETTINGS!$B$2*P36),2) | H36: 111.17895 | I36: -45.82 | J36: 0 | K36: 42.019372 | L36: 226.14685 | M36: 36 | N36: 0.83333333 | O36: 0.47455212 | P36: 0.52544788 | Q36: 0.32888422 | R36: higher | S36: FALSE | U36: no | V36: 31.74877 | W36: standard | X36: ACT | Y36: 00-0033293
A37: 36 | B37: Tyjae Spears | C37: TEN | D37: RB | E37: 6.61 | F37: 76.83 | G37: =ROUND(100*((1-SETTINGS!$B$2)*N37+SETTINGS!$B$2*P37),2) | H37: 110.98337 | I37: -46.01 | J37: 0 | K37: 41.823791 | L37: 225.95127 | M37: 37 | N37: 0.82857143 | O37: 0.47285341 | P37: 0.52714659 | Q37: 0.33058293 | R37: higher | S37: FALSE | U37: no | V37: 25.213387 | W37: standard | X37: ACT | Y37: 00-0039032
A38: 37 | B38: David Montgomery | C38: HOU | D38: RB | E38: 5.83 | F38: 76.81 | G38: =ROUND(100*((1-SETTINGS!$B$2)*N38+SETTINGS!$B$2*P38),2) | H38: 114.74878 | I38: -42.25 | J38: 0 | K38: 45.589197 | L38: 229.71667 | M38: 35 | N38: 0.83809524 | O38: 0.5118877 | P38: 0.4881123 | Q38: 0.29154864 | R38: higher | S38: FALSE | U38: no | V38: 29.235371 | W38: standard | X38: ACT | Y38: 00-0035685
A39: 38 | B39: Alvin Kamara | C39: NO | D39: RB | E39: 7.69 | F39: 76.76 | G39: =ROUND(100*((1-SETTINGS!$B$2)*N39+SETTINGS!$B$2*P39),2) | H39: 100.32774 | I39: -56.67 | J39: 0 | K39: 31.168158 | L39: 215.29564 | M39: 40 | N39: 0.81428571 | O39: 0.41893456 | P39: 0.58106544 | Q39: 0.38450178 | R39: higher | S39: FALSE | U39: no | V39: 31.105362 | W39: standard | X39: ACT | Y39: 00-0033906
A40: 39 | B40: Tyler Allgeier | C40: AZ | D40: RB | E40: 8.41 | F40: 76.72 | G40: =ROUND(100*((1-SETTINGS!$B$2)*N40+SETTINGS!$B$2*P40),2) | H40: 88.847803 | I40: -68.15 | J40: 0 | K40: 19.688222 | L40: 203.8157 | M40: 42 | N40: 0.8047619 | O40: 0.38302601 | P40: 0.61697399 | Q40: 0.42041033 | R40: higher | S40: FALSE | U40: no | V40: 26.379734 | W40: standard | X40: ACT | Y40: 00-0037263
...

Sheet WR
A1: Rank | B1: Player | C1: Team | D1: Pos | E1: Overall Draft Score (replacement-adjusted) | F1: Position Draft Score (default weight) | G1: Custom-Weight Score (weight from SETTINGS) | H1: Projected 2026 Points | I1: Points Over Replacement | J1: Overall Value (points over replacement / max) | K1: Points P10 | L1: Points P90 | M1: Pos Points Rank | N1: Pos Points Percentile | O1: Missed-Time Injury Probability | P1: Healthy Probability | Q1: Healthy Probability vs Position Mean (+0.5) | R1: Injury Risk Band | S1: Current Injury Listing (screen date) | T1: Current Listing Status | U1: Rookie | V1: Age | W1: Points Model Confidence | X1: Roster Status (Aug 9) | Y1: Player ID
A2: 1 | B2: Ja'Marr Chase | C2: CIN | D2: WR | E2: 65.83 | F2: 91.81 | G2: =ROUND(100*((1-SETTINGS!$B$2)*N2+SETTINGS!$B$2*P2),2) | H2: 215.27921 | I2: 92.79 | J2: 0.7292 | K2: 147.48739 | L2: 297.55999 | M2: 4 | N2: 0.9921875 | O2: 0.37819061 | P2: 0.62180939 | Q2: 0.37466292 | R2: higher | S2: FALSE | U2: no | V2: 26.502939 | W2: standard | X2: ACT | Y2: 00-0036900
A3: 2 | B3: George Pickens | C3: DAL | D3: WR | E3: 63.88 | F3: 91.25 | G3: =ROUND(100*((1-SETTINGS!$B$2)*N3+SETTINGS!$B$2*P3),2) | H3: 212.40207 | I3: 89.92 | J3: 0.7066 | K3: 144.61025 | L3: 294.68285 | M3: 6 | N3: 0.98697917 | O3: 0.38547724 | P3: 0.61452276 | Q3: 0.36737629 | R3: higher | S3: FALSE | U3: no | V3: 25.49539 | W3: standard | X3: ACT | Y3: 00-0037247
A4: 3 | B4: Amon-Ra St. Brown | C4: DET | D4: WR | E4: 75.19 | F4: 91.13 | G4: =ROUND(100*((1-SETTINGS!$B$2)*N4+SETTINGS!$B$2*P4),2) | H4: 231.91781 | I4: 109.43 | J4: 0.86 | K4: 164.12599 | L4: 314.19859 | M4: 2 | N4: 0.99739583 | O4: 0.43314403 | P4: 0.56685597 | Q4: 0.3197095 | R4: higher | S4: FALSE | U4: no | V4: 26.856131 | W4: standard | X4: ACT | Y4: 00-0036963
A5: 4 | B5: Justin Jefferson | C5: MIN | D5: WR | E5: 63.83 | F5: 91.03 | G5: =ROUND(100*((1-SETTINGS!$B$2)*N5+SETTINGS!$B$2*P5),2) | H5: 213.00414 | I5: 90.52 | J5: 0.7114 | K5: 145.21232 | L5: 295.28492 | M5: 5 | N5: 0.98958333 | O5: 0.4070599 | P5: 0.5929401 | Q5: 0.34579363 | R5: higher | S5: FALSE | U5: no | V5: 27.212057 | W5: standard | X5: ACT | Y5: 00-0036322
A6: 5 | B6: Jaxon Smith-Njigba | C6: SEA | D6: WR | E6: 85.74 | F6: 90.68 | G6: =ROUND(100*((1-SETTINGS!$B$2)*N6+SETTINGS!$B$2*P6),2) | H6: 249.73827 | I6: 127.25 | J6: 1 | K6: 181.94645 | L6: 332.01905 | M6: 1 | N6: 1 | O6: 0.46595868 | P6: 0.53404132 | Q6: 0.28689485 | R6: higher | S6: FALSE | U6: no | V6: 24.545336 | W6: standard | X6: ACT | Y6: 00-0038543
A7: 6 | B7: Puka Nacua | C7: LA | D7: WR | E7: 74.24 | F7: 90.38 | G7: =ROUND(100*((1-SETTINGS!$B$2)*N7+SETTINGS!$B$2*P7),2) | H7: 231.26732 | I7: 108.78 | J7: 0.8549 | K7: 163.4755 | L7: 313.5481 | M7: 3 | N7: 0.99479167 | O7: 0.46033059 | P7: 0.53966941 | Q7: 0.29252294 | R7: higher | S7: TRUE | T7: Questionable | U7: no | V7: 25.25993 | W7: standard | X7: ACT | Y7: 00-0039075
A8: 7 | B8: Chris Olave | C8: NO | D8: WR | E8: 42.78 | F8: 89.86 | G8: =ROUND(100*((1-SETTINGS!$B$2)*N8+SETTINGS!$B$2*P8),2) | H8: 178.73788 | I8: 56.25 | J8: 0.442 | K8: 110.94606 | L8: 261.01867 | M8: 13 | N8: 0.96875 | O8: 0.38199551 | P8: 0.61800449 | Q8: 0.37085802 | R8: higher | S8: FALSE | U8: no | V8: 26.179867 | W8: standard | X8: ACT | Y8: 00-0037239
A9: 8 | B9: Zay Flowers | C9: BAL | D9: WR | E9: 59.1 | F9: 89.65 | G9: =ROUND(100*((1-SETTINGS!$B$2)*N9+SETTINGS!$B$2*P9),2) | H9: 206.67381 | I9: 84.19 | J9: 0.6616 | K9: 138.88199 | L9: 288.95459 | M9: 8 | N9: 0.98177083 | O9: 0.44443044 | P9: 0.55556956 | Q9: 0.30842309 | R9: higher | S9: FALSE | U9: no | V9: 25.971786 | W9: standard | X9: ACT | Y9: 00-0039064
A10: 9 | B10: CeeDee Lamb | C10: DAL | D10: WR | E10: 58.45 | F10: 89.03 | G10: =ROUND(100*((1-SETTINGS!$B$2)*N10+SETTINGS!$B$2*P10),2) | H10: 206.9714 | I10: 84.49 | J10: 0.664 | K10: 139.17958 | L10: 289.25218 | M10: 7 | N10: 0.984375 | O10: 0.48621738 | P10: 0.51378262 | Q10: 0.26663615 | R10: higher | S10: FALSE | U10: no | V10: 27.400974 | W10: standard | X10: ACT | Y10: 00-0036358
A11: 10 | B11: Jameson Williams | C11: DET | D11: WR | E11: 54.7 | F11: 88.93 | G11: =ROUND(100*((1-SETTINGS!$B$2)*N11+SETTINGS!$B$2*P11),2) | H11: 200.4812 | I11: 78 | J11: 0.613 | K11: 132.68938 | L11: 282.76198 | M11: 9 | N11: 0.97916667 | O11: 0.47008001 | P11: 0.52991999 | Q11: 0.28277352 | R11: higher | S11: FALSE | U11: no | V11: 25.435156 | W11: standard | X11: ACT | Y11: 00-0037240
A12: 11 | B12: Nico Collins | C12: HOU | D12: WR | E12: 40.99 | F12: 87.95 | G12: =ROUND(100*((1-SETTINGS!$B$2)*N12+SETTINGS!$B$2*P12),2) | H12: 179.27048 | I12: 56.78 | J12: 0.4462 | K12: 111.47866 | L12: 261.55126 | M12: 12 | N12: 0.97135417 | O12: 0.48793958 | P12: 0.51206042 | Q12: 0.26491395 | R12: higher | S12: FALSE | U12: no | V12: 27.455732 | W12: standard | X12: ACT | Y12: 00-0036554
A13: 12 | B13: Jaylen Waddle | C13: DEN | D13: WR | E13: 40.4 | F13: 87.71 | G13: =ROUND(100*((1-SETTINGS!$B$2)*N13+SETTINGS!$B$2*P13),2) | H13: 178.02173 | I13: 55.54 | J13: 0.4365 | K13: 110.22991 | L13: 260.30251 | M13: 14 | N13: 0.96614583 | O13: 0.47908948 | P13: 0.52091052 | Q13: 0.27376405 | R13: higher | S13: TRUE | T13: Questionable | U13: no | V13: 27.767853 | W13: standard | X13: ACT | Y13: 00-0036613
A14: 13 | B14: Drake London | C14: ATL | D14: WR | E14: 52.09 | F14: 87.69 | G14: =ROUND(100*((1-SETTINGS!$B$2)*N14+SETTINGS!$B$2*P14),2) | H14: 197.9819 | I14: 75.5 | J14: 0.5933 | K14: 130.19008 | L14: 280.26269 | M14: 10 | N14: 0.9765625 | O14: 0.52163641 | P14: 0.47836359 | Q14: 0.23121712 | R14: higher | S14: FALSE | U14: no | V14: 25.106607 | W14: standard | X14: ACT | Y14: 00-0037238
A15: 14 | B15: A.J. Brown | C15: NE | D15: WR | E15: 39.58 | F15: 87.66 | G15: =ROUND(100*((1-SETTINGS!$B$2)*N15+SETTINGS!$B$2*P15),2) | H15: 176.48154 | I15: 54 | J15: 0.4244 | K15: 108.68972 | L15: 258.76232 | M15: 15 | N15: 0.96354167 | O15: 0.47129817 | P15: 0.52870183 | Q15: 0.28155536 | R15: higher | S15: FALSE | U15: no | V15: 29.1724 | W15: standard | X15: ACT | Y15: 00-0035676
A16: 15 | B16: DeVonta Smith | C16: PHI | D16: WR | E16: 38.66 | F16: 87.49 | G16: =ROUND(100*((1-SETTINGS!$B$2)*N16+SETTINGS!$B$2*P16),2) | H16: 174.96752 | I16: 52.48 | J16: 0.4124 | K16: 107.1757 | L16: 257.2483 | M16: 16 | N16: 0.9609375 | O16: 0.46928457 | P16: 0.53071543 | Q16: 0.28356896 | R16: higher | S16: TRUE | T16: Questionable | U16: no | V16: 27.79797 | W16: standard | X16: ACT | Y16: 00-0036912
A17: 16 | B17: Tetairoa McMillan | C17: CAR | D17: WR | E17: 43.19 | F17: 87.24 | G17: =ROUND(100*((1-SETTINGS!$B$2)*N17+SETTINGS!$B$2*P17),2) | H17: 184.2247 | I17: 61.74 | J17: 0.4852 | K17: 116.43288 | L17: 266.50548 | M17: 11 | N17: 0.97395833 | O17: 0.53396651 | P17: 0.46603349 | Q17: 0.21888702 | R17: higher | S17: FALSE | U17: no | V17: 23.409105 | W17: standard | X17: ACT | Y17: 00-0040124
A18: 17 | B18: Wan'Dale Robinson | C18: TEN | D18: WR | E18: 36.18 | F18: 86.88 | G18: =ROUND(100*((1-SETTINGS!$B$2)*N18+SETTINGS!$B$2*P18),2) | H18: 171.65199 | I18: 49.17 | J18: 0.3864 | K18: 103.86017 | L18: 253.93278 | M18: 17 | N18: 0.95833333 | O18: 0.48954781 | P18: 0.51045219 | Q18: 0.26330572 | R18: higher | S18: FALSE | U18: no | V18: 25.654188 | W18: standard | X18: ACT | Y18: 00-0038117
A19: 18 | B19: Davante Adams | C19: LA | D19: WR | E19: 31.12 | F19: 86.65 | G19: =ROUND(100*((1-SETTINGS!$B$2)*N19+SETTINGS!$B$2*P19),2) | H19: 162.3029 | I19: 39.82 | J19: 0.3129 | K19: 94.511082 | L19: 244.58368 | M19: 22 | N19: 0.9453125 | O19: 0.44855853 | P19: 0.55144147 | Q19: 0.30429499 | R19: higher | S19: FALSE | U19: no | V19: 33.687206 | W19: standard | X19: ACT | Y19: 00-0031381
